Workbook

Sheet Pruebas Estandar 
B1: Casos de Pruebas Estándar
B3: Marcar solo después de ejecutar: OK cumple, NC no cumple, NA no aplica con justificación y BL bloqueado por una dependencia pendiente. Estado vacío significa pendiente.
B4: Alcance: Aprueba Administración. Los resultados iniciales están pendientes; las observaciones del equipo no equivalen a pruebas ejecutadas.
A6: ID | B6: 1.- INTERFAZ GRÁFICA. | D6: Estado
A7: E-1.1 | B7: Navegación identifica la sección activa y permite regresar. | D7: OK
A8: E-1.2 | B8: Tabla y gráfico de Sponsors se visualizan completos. | D8: OK
A9: E-1.3 | B9: Botones de edición y eliminación son accesibles. | D9: OK
A10: E-1.4 | B10: Formularios presentan etiquetas y campos obligatorios. | D10: OK
A11: E-1.5 | B11: Confirmaciones de eliminación se muestran sobre la ficha. | D11: OK
A12: E-1.6 | B12: Ficha de tutor permite cambiar la selección. | D12: OK
A13: E-1.7 | B13: Avatar de tutor no se recorta en teléfono. | D13: OK
A14: E-1.8 | B14: Contraste legible en tema claro. | D14: OK
A15: E-1.9 | B15: Contraste legible en tema oscuro. | D15: OK
A16: E-1.10 | B16: Contador de Recorrecciones legible en pestaña activa. | D16: OK
A17: E-1.11 | B17: KPI e iconos de Resumen y Tutores sin cortes. | D17: OK
... A22: E-1.16 | B22: Flujo prioritario compatible con Chrome y Edge. | D22: OK
A24: ID | B24: 2.- VALIDACIÓN DE DATOS DE ENTRADA
A25: E-2.1 | B25: Nombre obligatorio del sponsor validado. | D25: OK
A26: E-2.2 | B26: Campos obligatorios del beneficio validados. | D26: OK
A27: E-2.3 | B27: Costo negativo rechazado. | D27: OK
A28: E-2.4 | B28: Costo no numérico rechazado. | D28: OK
A29: E-2.5 | B29: Stock negativo rechazado. | D29: OK
A30: E-2.6 | B30: Stock entero validado según contrato. | D30: OK
A31: E-2.7 | B31: Stock cero tratado según disponibilidad. | D31: OK
A32: E-2.8 | B32: Rango de fechas invertido rechazado. | D32: OK
A33: E-2.9 | B33: Vigencia vencida impide canje. | D33: OK
A34: E-2.10 | B34: Saldo insuficiente impide canje. | D34: BL
A35: E-2.11 | B35: Referencias inexistentes no crean registros huérfanos. | D35: OK
A36: E-2.12 | B36: Entradas inválidas de API no alteran datos. | D36: OK
... A41: E-2.17 | B41: Campos y tipos cumplen modelo administrativo vigente. | D41: OK
A43: ID | B43: 3.- PRUEBAS FUNCIONALES
A44: E-3.1 | B44: Login y MFA válido permiten acceso a Resumen. | D44: OK
A45: E-3.2 | B45: JWT ausente o vencido impide acceso. | D45: OK
A46: E-3.3 | B46: Permisos se validan en backend por rol. | D46: OK
A47: E-3.4 | B47: Cierre de sesión protege las rutas. | D47: OK
A48: E-3.5 | B48: Sponsor con beneficios se crea y persiste. | D48: OK
A49: E-3.6 | B49: Edición conserva asociación sponsor-beneficio. | D49: OK
A50: E-3.7 | B50: Cancelación de eliminación conserva registro. | D50: OK
A51: E-3.8 | B51: Eliminación respeta dependencias. | D51: OK
A52: E-3.9 | B52: Aporte mensual se registra en periodo correcto. | D52: OK
...

Sheet Casos de Prueba
C2: PLANILLA CASOS DE PRUEBA
B4: PROYECTO | D4: Aprueba Administración
B5: MODULOS | D5: Sponsors y Beneficios, identidad y módulos complementarios
B6: NOMBRE JEFE DE PROYECTO | D6: David Arenas Márquez
B7: NOMBRE ANALISTA TESTING | D7: Amaru Rojas Justiniano
B8: Nº CICLO | D8: 1
B9: FECHA | D9: 46304.5
A12: ID | B12: MODULO | C12: DESCRIPCIÓN DE CASOS DE PRUEBAS ( QUE PROBAR ) | D12: PROCEDIMIENTO DE PRUEBA (COMO) | E12: DATOS DE PRUEBA (CON QUE PROBAR) | F12: RESULTADO ESPERADO | G12: RESULTADO OBTENIDO | L12: ESTADO
G13: SI | H13: NO | I13: N/A | J13: Descripción | K13: Observación
A14: 1 | B14: Ambiente | C14: Preparar emulador y semilla | D14: 1. Iniciar emulador según repo. 2. Confirmar destino local del backend. 3. Ejecutar script seed:emu. 4. Consultar registros sembrados. | E14: Configuración local y semilla del repo. | F14: La semilla termina sin errores, carga los datos esperados y no modifica el ambiente compartido. | G14: =IF($L14="Aprobado","x","") -> x | H14: =IF($L14="Fallido","x","") | I14: =IF($L14="No aplica","x","") | J14: Semilla seed:emu ejecutada sin errores en el emulador (salida de probar-todo). Falta registrar fecha y commit. | K14: Prioridad alta. Responsable propuesto: backend. Registrar evidencia, fecha, commit y ambiente. | L14: Aprobado
A15: 2 | B15: Integración | C15: Ejecutar smoke de 110 comprobaciones | D15: 1. Preparar emulador con seed:emu. 2. Ejecutar comando smoke definido en repo. 3. Guardar salida completa y conteos. | E15: Commit fijado, emulador y semilla restaurada. | F15: 110 comprobaciones aprobadas, cero fallas u omisiones. Si cambió la suite, justificar y actualizar línea base. | G15: =IF($L15="Aprobado","x","") -> x | H15: =IF($L15="Fallido","x","") | I15: =IF($L15="No aplica","x","") | J15: Smoke: 110 comprobaciones OK, 0 fallas (ejecutado en el emulador tras seed:emu). Falta guardar la salida con fecha y commit. | K15: El equipo reporta esta suite. Verificar comando y cobertura en repo. No se han ejecutado sus comprobaciones en esta planilla. | L15: Aprobado
A16: 3 | B16: Identidad | C16: Iniciar sesión y aterrizar en Resumen | D16: 1. Abrir login desde otra ruta. 2. Ingresar credenciales válidas. 3. Completar MFA válido. | E16: Administrador de prueba y OTP legítimo. | F16: Se crea sesión autorizada y abre Resumen sin quedar en la ruta anterior. | G16: =IF($L16="Aprobado","x","") -> x | H16: =IF($L16="Fallido","x","") | I16: =IF($L16="No aplica","x","") | J16: Verificado por el equipo (pruebas estándar E-3.1). | K16: Prioridad alta. Responsable propuesto: backend. Registrar evidencia, fecha, commit y ambiente. | L16: Aprobado
A17: 4 | B17: Identidad | C17: Rechazar credenciales inválidas | D17: 1. Probar contraseña incorrecta. 2. Probar usuario inexistente. 3. Consultar ruta protegida. | E17: Cuenta de prueba, clave incorrecta y correo inexistente. | F17: No se emite sesión válida ni se accede a datos protegidos. Mensaje sin revelar secretos. | G17: =IF($L17="Aprobado","x","") -> x | H17: =IF($L17="Fallido","x","") | I17: =IF($L17="No aplica","x","") | J17: Verificado por el equipo (pruebas estándar E-2.13). | K17: Prioridad alta. Responsable propuesto: backend. Registrar evidencia, fecha, commit y ambiente. | L17: Aprobado
A18: 5 | B18: Seguridad | C18: SEG-01 invalidar credenciales publicadas | D18: 1. Revisar README actual e historial sin copiar secretos a la evidencia. 2. Verificar retiro e invalidación. 3. Intentar acceso controlado con credencial expuesta. | E18: Cuenta afectada, entorno autorizado y credencial expuesta identificada por el equipo. | F18: No hay contraseñas operativas publicadas; las credenciales expuestas están invalidadas y no permiten iniciar sesión. | G18: =IF($L18="Aprobado","x","") | H18: =IF($L18="Fallido","x","") -> x | I18: =IF($L18="No aplica","x","") | J18: Defecto conocido abierto: las contraseñas sembradas siguen en el README y en la semilla. Pendiente corregir y revalidar. | K18: Defecto conocido reportado. Crítico provisional si afecta despliegue. Reproducir antes de registrar resultado. Responsable: backend. | L18: Fallido
A19: 6 | B19: Seguridad | C19: SEG-02 rechazar MFA fijo | D19: 1. Preparar sesión pendiente de MFA. 2. Enviar código fijo reportado. 3. Verificar rechazo en ambiente desplegado autorizado. | E19: Cuenta de prueba y código fijo de demostración. | F19: El código fijo no habilita acceso administrativo. Mecanismo de prueba aislado al emulador. | G19: =IF($L19="Aprobado","x","") | H19: =IF($L19="Fallido","x","") -> x | I19: =IF($L19="No aplica","x","") | J19: Defecto conocido abierto: el código MFA fijo de demostración sigue activo. Pendiente aislarlo al emulador. | K19: Defecto conocido reportado. Bloquea cierre si afecta despliegue. No atribuir resultado sin ejecución. Responsable: backend. | L19: Fallido
A20: 7 | B20: Seguridad | C20: Validar vencimiento y uso único OTP | D20: 1. Probar OTP incorrecto. 2. Probar OTP vencido. 3. Completar uno válido. 4. Reutilizar el mismo. | E20: Códigos controlados y política OTP vigente. | F20: Solo el código válido y vigente (ventana de ±1 período TOTP de 30 s) se acepta; los incorrectos y vencidos se rechazan. El rechazo de un código ya usado se verifica solo si el contrato lo exige; de lo contrario se registra como mejora propia. | G20: =IF($L20="Aprobado","x","") | H20: =IF($L20="Fallido","x","") | I20: =IF($L20="No aplica","x","") | J20: Bloqueado: el TOTP real aún no está implementado; hoy se usa un código fijo. | K20: Prioridad alta. Responsable propuesto: backend. Registrar evidencia, fecha, commit y ambiente. Los documentos de Max piden TOTP con ventana de tolerancia y no exigen uso único del código. | L20: Bloqueado
A21: 8 | B21: Seguridad | C21: Rechazar token ausente o vencido | D21: 1. Consultar ruta admin sin JWT. 2. Repetir con JWT vencido. 3. Revisar respuesta y datos. | E21: Ruta admin real y token vencido de prueba. | F21: Se rechaza el acceso según contrato, sin exponer datos administrativos. | G21: =IF($L21="Aprobado","x","") -> x | H21: =IF($L21="Fallido","x","") | I21: =IF($L21="No aplica","x","") | J21: Sin token → 401 (smoke). Token vencido → 401 "Token inválido o expirado": el backend verifica la expiración del JWT (vigencia de 15 minutos). | K21: Prioridad alta. Responsable propuesto: backend. Registrar evidencia, fecha, commit y ambiente. | L21: Aprobado
A22: 9 | B22: Seguridad | C22: Aplicar permisos por rol en API | D22: 1. Acceder con rol autorizado. 2. Repetir consulta y mutación con rol restringido mediante API directa. | E22: Cuentas de roles definidos en el contrato vigente. | F22: Solo roles permitidos ejecutan la operación; ocultar botones no sustituye la validación del backend. | G22: =IF($L22="Aprobado","x","") -> x | H22: =IF($L22="Fallido","x","") | I22: =IF($L22="No aplica","x","") | J22: Verificado por el equipo (pruebas estándar E-3.3). | K22: Prioridad alta. Responsable propuesto: backend. Registrar evidencia, fecha, commit y ambiente. | L22: Aprobado
A23: 10 | B23: Identidad | C23: Cerrar sesión | D23: 1. Iniciar sesión. 2. Cerrar sesión. 3. Volver a ruta protegida y recargar. | E23: Cuenta de prueba autorizada. | F23: La interfaz exige autenticarse nuevamente. Verificar invalidación de sesión conforme a política vigente. | G23: =IF($L23="Aprobado","x","") -> x | H23: =IF($L23="Fallido","x","") | I23: =IF($L23="No aplica","x","") | J23: Verificado por el equipo (pruebas estándar E-3.4). | K23: Prioridad alta. Responsable propuesto: backend. Registrar evidencia, fecha, commit y ambiente. | L23: Aprobado
A24: 11 | B24: API | C24: Validar contrato de respuestas | D24: 1. Ejecutar consulta válida, entrada inválida y recurso inexistente. 2. Comparar respuestas con contrato admin vigente. | E24: Endpoints reales y referencia Aprueba_Admin_API_FastAPI. | F24: Código HTTP, estructura y campos cumplen el contrato vigente. Contrastar envoltorio implementado {data, error, meta}. | G24: =IF($L24="Aprobado","x","") | H24: =IF($L24="Fallido","x","") | I24: =IF($L24="No aplica","x","") | J24: Smoke verifica códigos HTTP y estructura {data, error, meta}. Falta contrastar con el documento de Max. | K24: Prioridad alta. Responsable propuesto: backend. Registrar evidencia, fecha, commit y ambiente. | L24: En ejecución
A25: 12 | B25: Sponsors | C25: Consultar tabla y gráfico | D25: 1. Sembrar sponsors con aportes conocidos. 2. Abrir módulo. 3. Comparar tabla, gráfico y fuente de datos. | E25: Sponsor A aporte 100000 y B aporte 50000 en el mismo mes. | F25: Tabla y gráfico representan ambos sponsors y sus aportes sin omisiones ni duplicados. | G25: =IF($L25="Aprobado","x","") -> x | H25: =IF($L25="Fallido","x","") | I25: =IF($L25="No aplica","x","") | J25: Criterio oficial 1 verificado por el equipo; smoke confirma 5 sponsors con beneficios. Falta adjuntar captura. | K25: Prioridad alta. D-E4. Responsables propuestos: ambos. Verificar interfaz, API y persistencia. | L25: Aprobado
... A61: 48 | B61: Regresión | C61: Repetir después de corregir defectos | D61: 1. Aplicar corrección en commit nuevo. 2. Restaurar semilla. 3. Repetir smoke, caso afectado y dependencias. | E61: Commit corregido y semilla equivalente al ciclo anterior. | F61: Smoke aprobada y defecto revalidado sin regresiones. Documentar cada ejecución y versión. | G61: =IF($L61="Aprobado","x","") | H61: =IF($L61="Fallido","x","") | I61: =IF($L61="No aplica","x","") | J61: Pendiente de ejecución | K61: Responsables propuestos: ambos. El estado no se hereda de una ejecución anterior. | L61: Pendiente

Sheet Totales
B1: Resumen de pruebas de Aprueba Administración
B4: Total Pruebas Estándar OK | C4: =COUNTIF('Pruebas Estandar '!D7:D77,"OK") -> 49
B5: Total Pruebas Estándar NO CUMPLE | C5: =COUNTIF('Pruebas Estandar '!D7:D77,"NC") -> 2
B6: Total Pruebas Estándar NO APLICA | C6: =COUNTIF('Pruebas Estandar '!D7:D77,"NA") -> 0
B7: Total pruebas estándar pendientes | C7: =61-SUM(C4:C6)-C8 -> 5
B8: Total Pruebas Estándar BLOQUEADAS | C8: =COUNTIF('Pruebas Estandar '!D7:D77,"BL") -> 5
B11: Total casos de Prueba | C11: =COUNTA('Casos de Prueba'!A14:A61) -> 48
B12: Total casos de Prueba OK | C12: =COUNTIF('Casos de Prueba'!G14:G61,"x") -> 36
B13: Total casos de Prueba NO OK | C13: =COUNTIF('Casos de Prueba'!H14:H61,"x") -> 2
B14: Total casos de Prueba NO Aplica | C14: =COUNTIF('Casos de Prueba'!I14:I61,"x") -> 0
B15: Total casos de Prueba No revisados | C15: =C11-SUM(C12:C14) -> 10
B16: de los cuales bloqueados | C16: =COUNTIF('Casos de Prueba'!L14:L61,"Bloqueado") -> 3
B17: Comprobaciones smoke reportadas | C17: 110
B18: Ejecución smoke de este ciclo | D18: Ejecutada: 110 comprobaciones OK en el emulador. Falta conservar salida, fecha y commit.
B20: SEG-01 y SEG-02: defectos conocidos reportados; reproducir y revalidar. El cierre integral exige cero críticos o altos abiertos.
B22: Fuentes: Plan de Pruebas revisión 1.2 y antecedentes del equipo al 09/10/2026.
B23: Referencias vigentes: Aprueba_Admin_API_FastAPI y Aprueba_Admin_Modelo_Datos_Firestore.
B24: La smoke es una suite de 110 comprobaciones; se registra como un caso de ejecución, no como 110 casos inventados.
B25: En cada caso marcar una sola x en SI, NO o N/A. Registrar resultado real en Descripción y evidencia, fecha, commit y ambiente en Observación.
B26: Datos académicos y responsables nominales de la cabecera se completan después. Las observaciones indican responsable propuesto por rol.
B27: El cierre funcional reportado de Sponsors no acredita ejecución de esta planilla ni aceptación final de seguridad.
B28: Los contratos y campos exactos se contrastan con Aprueba_Admin_API_FastAPI y Aprueba_Admin_Modelo_Datos_Firestore antes de ejecutar. Tutores y Contenido no figuran en esos documentos; se contrastan con el README del repo.
B29: Estado de cada caso: columna ESTADO de la hoja Casos de Prueba (Pendiente, En ejecución, Aprobado, Fallido, Bloqueado o No aplica). Las columnas SI, NO y N/A se calculan automáticamente a partir del estado; no se marcan a mano.
